Workbook

Sheet DATA
A1: Sector | B1: Year | C1: PE Ratio | D1: EV/EBITDA | E1: Price-to-Book | F1: PEG Ratio | G1: ROIC | H1: FCF Yield | I1: Dividend Yield | J1: Payout Ratio | K1: Current Ratio | L1: ROE | M1: Debt/Equity | N1: Net Profit Margin | O1: Gross Margin | P1: Revenue Growth | Q1: Net Income Growth
A2: Basic Materials | B2: 2011 | C2: 11.195 | D2: 5.984 | E2: 1.411 | F2: 2.409 | G2: -0.03 | H2: -0.021 | I2: 0 | J2: 0 | K2: 2.391 | L2: -0.029 | M2: 0.002 | N2: 0.052 | O2: 0.389
A3: Basic Materials | B3: 2012 | C3: 16.232 | D3: 1.701 | E3: 1.381 | F3: 0.008 | G3: -0.044 | H3: -0.056 | I3: 0 | J3: 0 | K3: 2.279 | L3: -0.052 | M3: 0.038 | N3: 0.017 | O3: 0.34 | P3: -0.004 | Q3: -0.22
A4: Basic Materials | B4: 2013 | C4: 19.911 | D4: 0.618 | E4: 1.462 | F4: 0.019 | G4: -0.049 | H4: -0.028 | I4: 0 | J4: 0 | K4: 1.943 | L4: -0.05 | M4: 0.054 | N4: 0.028 | O4: 0.337 | P4: 0.019 | Q4: -0.095
A5: Basic Materials | B5: 2014 | C5: 26.213 | D5: 0.989 | E5: 1.61 | F5: 1.248 | G5: -0.04 | H5: -0.039 | I5: 0 | J5: 0 | K5: 1.999 | L5: -0.048 | M5: 0.047 | N5: 0.038 | O5: 0.328 | P5: 0.054 | Q5: -0.061
A6: Basic Materials | B6: 2015 | C6: 22.294 | D6: 0.065 | E6: 1.439 | F6: 0.035 | G6: -0.005 | H6: -0.029 | I6: 0 | J6: 0 | K6: 1.847 | L6: -0.019 | M6: 0.063 | N6: 0.035 | O6: 0.349 | P6: -0.06 | Q6: -0.032
A7: Basic Materials | B7: 2016 | C7: 18.319 | D7: 1.274 | E7: 1.407 | F7: 0.639 | G7: -0.006 | H7: -0.02 | I7: 0 | J7: 0 | K7: 1.943 | L7: 0 | M7: 0.048 | N7: 0.07 | O7: 0.344 | P7: 0.06 | Q7: -0.003
A8: Basic Materials | B8: 2017 | C8: 25.457 | D8: 2.076 | E8: 1.535 | F8: 0.005 | G8: -0.007 | H8: -0.017 | I8: 0 | J8: 0 | K8: 2.064 | L8: 0.002 | M8: 0.124 | N8: 0.05 | O8: 0.354 | P8: 0.186 | Q8: 0.052
A9: Basic Materials | B9: 2018 | C9: 23.088 | D9: 1.422 | E9: 1.406 | F9: 0.004 | G9: 0 | H9: -0.033 | I9: 0 | J9: 0 | K9: 2.03 | L9: -0.037 | M9: 0.084 | N9: 0.05 | O9: 0.372 | P9: 0.094 | Q9: 0.049
A10: Basic Materials | B10: 2019 | C10: 23.021 | D10: 0.645 | E10: 1.397 | F10: 32.101 | G10: 0.011 | H10: -0.027 | I10: 0 | J10: 0 | K10: 1.692 | L10: 0 | M10: 0.105 | N10: 0.049 | O10: 0.336 | P10: 0.04 | Q10: -0.078
A11: Basic Materials | B11: 2020 | C11: 32.641 | D11: 2.058 | E11: 1.551 | F11: 0.423 | G11: -0.008 | H11: -0.002 | I11: 0 | J11: 0 | K11: 2.09 | L11: -0.018 | M11: 0.112 | N11: 0.043 | O11: 0.326 | P11: -0.036 | Q11: -0.128
A12: Basic Materials | B12: 2021 | C12: 19.004 | D12: 0.907 | E12: 1.997 | F12: 0.005 | G12: -0.05 | H12: -0.026 | I12: 0 | J12: 0 | K12: 2.173 | L12: -0.01 | M12: 0.04 | N12: 0.082 | O12: 0.34 | P12: 0.269 | Q12: 0.323
A13: Basic Materials | B13: 2022 | C13: 19.825 | D13: 0.305 | E13: 1.131 | F13: 0.484 | G13: -0.017 | H13: -0.061 | I13: 0 | J13: 0 | K13: 1.9 | L13: -0.041 | M13: 0.084 | N13: 0.056 | O13: 0.367 | P13: 0.088 | Q13: -0.121
A14: Basic Materials | B14: 2023 | C14: 23.078 | D14: 7.241 | E14: 1.003 | F14: 0.25 | G14: -0.024 | H14: -0.089 | I14: 0 | J14: 0 | K14: 1.839 | L14: -0.033 | M14: 0.094 | N14: 0.026 | O14: 0.346 | P14: -0.057 | Q14: -0.235
... A16: Basic Materials | B16: 2025 | C16: 6.027 | D16: 5.06 | E16: 1.44 | F16: 1.096 | G16: 0.041 | H16: 0.03 | I16: 0 | J16: 0 | K16: 1.987 | L16: 0.022 | M16: 0.224 | N16: 0.032 | O16: 0.332 | P16: 0.015 | Q16: -0.123
A17: Basic Materials | B17: 2026 | D17: 8.415 | E17: 1.582 | F17: 0.262 | G17: -0.094 | H17: 0.05 | I17: 0.04 | J17: -1.344 | K17: 1.555 | L17: -0.048 | M17: 0.697 | N17: -0.008 | O17: 0.05 | P17: 0.077 | Q17: -1.257
A18: Communication Services | B18: 2011 | C18: 12.026 | D18: 7.169 | E18: 1.629 | F18: 2 | G18: 0.059 | H18: 0.03 | I18: 0.006 | J18: 0 | K18: 0.934 | L18: 0.055 | M18: 0.287 | N18: 0.036 | O18: 0.604
A19: Communication Services | B19: 2012 | C19: 13.462 | D19: 8.909 | E19: 1.825 | F19: 0.012 | G19: 0.084 | H19: 0.045 | I19: 0.014 | J19: 0.277 | K19: 0.996 | L19: 0.09 | M19: 0.242 | N19: 0.066 | O19: 0.546 | P19: 0.031 | Q19: 0.184
A20: Communication Services | B20: 2013 | C20: 15.454 | D20: 10.988 | E20: 2.353 | F20: 0.037 | G20: 0.093 | H20: 0.044 | I20: 0.008 | J20: 0.235 | K20: 1.006 | L20: 0.094 | M20: 0.026 | N20: 0.085 | O20: 0.48 | P20: 0.069 | Q20: 0.133
A21: Communication Services | B21: 2014 | C21: 11.579 | D21: 10.11 | E21: 2.237 | F21: 0.135 | G21: 0.061 | H21: 0.032 | I21: 0.012 | J21: 0.173 | K21: 0.998 | L21: 0.079 | M21: 0.065 | N21: 0.064 | O21: 0.455 | P21: 0.036 | Q21: 0.011
A22: Communication Services | B22: 2015 | C22: 13.055 | D22: 10.134 | E22: 2.549 | F22: 0.033 | G22: 0.07 | H22: 0.021 | I22: 0.009 | J22: 0.298 | K22: 1.097 | L22: 0.087 | M22: 0.222 | N22: 0.06 | O22: 0.423 | P22: 0.061 | Q22: 0.019
A23: Communication Services | B23: 2016 | C23: 16.823 | D23: 9.194 | E23: 1.862 | F23: 2.465 | G23: 0.057 | H23: 0.041 | I23: 0.015 | J23: 0.306 | K23: 1.114 | L23: 0.055 | M23: 0.165 | N23: 0.041 | O23: 0.432 | P23: 0.123 | Q23: -0.162
A24: Communication Services | B24: 2017 | C24: 13.543 | D24: 9.731 | E24: 1.69 | F24: 0.01 | G24: 0.065 | H24: 0.036 | I24: 0.011 | J24: 0.237 | K24: 1.325 | L24: 0.082 | M24: 0.142 | N24: 0.045 | O24: 0.476 | P24: 0.124 | Q24: 0.221
A25: Communication Services | B25: 2018 | C25: 13.169 | D25: 10.19 | E25: 1.708 | F25: 0.061 | G25: 0.064 | H25: 0.047 | I25: 0.01 | J25: 0.043 | K25: 1.232 | L25: 0.065 | M25: 0.213 | N25: 0.045 | O25: 0.451 | P25: 0.094 | Q25: 0.036
A26: Communication Services | B26: 2019 | C26: 8.99 | D26: 9.499 | E26: 2.055 | F26: 0.05 | G26: 0.059 | H26: 0.031 | I26: 0.008 | J26: 0 | K26: 1.399 | L26: 0.043 | M26: 0.309 | N26: 0.033 | O26: 0.445 | P26: 0.06 | Q26: 0.062
A27: Communication Services | B27: 2020 | C27: 35.435 | D27: 8.912 | E27: 2.068 | F27: 0.122 | G27: 0.023 | H27: 0.032 | I27: 0 | J27: 0 | K27: 1.345 | L27: -0.01 | M27: 0.399 | N27: -0.006 | O27: 0.357 | P27: -0.066 | Q27: -0.479
A28: Communication Services | B28: 2021 | C28: 11.468 | D28: 9.267 | E28: 2.99 | F28: 1.197 | G28: 0.046 | H28: 0.03 | I28: 0 | J28: 0 | K28: 1.293 | L28: 0.037 | M28: 0.304 | N28: 0.035 | O28: 0.391 | P28: 0.128 | Q28: -0.158
A29: Communication Services | B29: 2022 | C29: 12.731 | D29: 7.818 | E29: 1.786 | F29: 0.033 | G29: 0.05 | H29: 0.044 | I29: 0.004 | J29: 0.014 | K29: 1.322 | L29: 0.051 | M29: 0.276 | N29: 0.053 | O29: 0.41 | P29: 0.18 | Q29: 0.07
A30: Communication Services | B30: 2023 | C30: 10.168 | D30: 7.079 | E30: 1.597 | F30: 0.013 | G30: 0.053 | H30: 0.047 | I30: 0.007 | J30: 0.036 | K30: 1.322 | L30: 0.062 | M30: 0.13 | N30: 0.029 | O30: 0.394 | P30: 0.075 | Q30: -0.373
... A33: Communication Services | B33: 2026 | C33: 19.313 | D33: 5.375 | E33: 2.682 | F33: 0.122 | G33: 0.116 | H33: 0.127 | I33: 0.035 | J33: -0.512 | K33: 1.13 | L33: -0.008 | M33: 1.04 | N33: -0.01 | O33: 0.315 | P33: 0.07 | Q33: -0.904
A34: Consumer Cyclical | B34: 2011 | C34: 10.191 | D34: 5.902 | E34: 1.27 | F34: 0.177 | G34: 0.065 | H34: 0.032 | I34: 0.016 | J34: 0.175 | K34: 1.293 | L34: 0.102 | M34: 0.144 | N34: 0.056 | O34: 0.485
A35: Consumer Cyclical | B35: 2012 | C35: 11.305 | D35: 7.049 | E35: 1.578 | F35: 0.009 | G35: 0.086 | H35: 0.039 | I35: 0.019 | J35: 0.213 | K35: 1.364 | L35: 0.119 | M35: 0.14 | N35: 0.051 | O35: 0.431 | P35: 0.066 | Q35: 0.106
A36: Consumer Cyclical | B36: 2013 | C36: 13.983 | D36: 8.855 | E36: 1.905 | F36: 0.018 | G36: 0.079 | H36: 0.034 | I36: 0.014 | J36: 0.223 | K36: 1.28 | L36: 0.105 | M36: 0.168 | N36: 0.051 | O36: 0.379 | P36: 0.088 | Q36: 0.036
A37: Consumer Cyclical | B37: 2014 | C37: 14.543 | D37: 9.007 | E37: 2.412 | F37: 0.155 | G37: 0.085 | H37: 0.046 | I37: 0.016 | J37: 0.235 | K37: 1.241 | L37: 0.132 | M37: 0.314 | N37: 0.047 | O37: 0.379 | P37: 0.099 | Q37: 0.154
A38: Consumer Cyclical | B38: 2015 | C38: 13.549 | D38: 9.164 | E38: 2.575 | F38: 0.092 | G38: 0.102 | H38: 0.034 | I38: 0.015 | J38: 0.263 | K38: 1.3 | L38: 0.144 | M38: 0.301 | N38: 0.049 | O38: 0.372 | P38: 0.088 | Q38: 0.142
A39: Consumer Cyclical | B39: 2016 | C39: 15.271 | D39: 8.981 | E39: 2.482 | F39: 0.151 | G39: 0.093 | H39: 0.037 | I39: 0.02 | J39: 0.297 | K39: 1.309 | L39: 0.152 | M39: 0.287 | N39: 0.051 | O39: 0.386 | P39: 0.108 | Q39: 0.058
A40: Consumer Cyclical | B40: 2017 | C40: 14.763 | D40: 9.853 | E40: 2.367 | F40: 0.088 | G40: 0.093 | H40: 0.036 | I40: 0.019 | J40: 0.301 | K40: 1.309 | L40: 0.14 | M40: 0.269 | N40: 0.052 | O40: 0.399 | P40: 0.111 | Q40: 0.075
A41: Consumer Cyclical | B41: 2018 | C41: 13.267 | D41: 9.353 | E41: 2.127 | F41: 0.007 | G41: 0.086 | H41: 0.044 | I41: 0.024 | J41: 0.308 | K41: 1.254 | L41: 0.131 | M41: 0.315 | N41: 0.048 | O41: 0.378 | P41: 0.078 | Q41: -0.001
A42: Consumer Cyclical | B42: 2019 | C42: 12.387 | D42: 9.178 | E42: 1.924 | F42: 1.142 | G42: 0.078 | H42: 0.048 | I42: 0.02 | J42: 0.293 | K42: 1.279 | L42: 0.073 | M42: 0.448 | N42: 0.037 | O42: 0.374 | P42: 0.048 | Q42: -0.118
A43: Consumer Cyclical | B43: 2020 | C43: 11.888 | D43: 9.798 | E43: 1.757 | F43: 0.525 | G43: 0.034 | H43: 0.06 | I43: 0.002 | J43: 0 | K43: 1.265 | L43: 0.027 | M43: 0.67 | N43: 0.016 | O43: 0.328 | P43: -0.031 | Q43: -0.35
...

Sheet CONTROL
B2: SECTOR MEDIANS | Interactive Dashboard Controls
B4: CHART 1: Metric Over Time (by Sector) | F4: CHART 2: All Sectors Snapshot (by Year)
B6: Select Sector: | C6: Basic Materials | F6: Select Year: | G6: 2024
B8: Select Metric: | C8: PE Ratio | F8: Select Metric: | G8: PE Ratio
B11: HOW TO USE:
B12: 1. Use the dropdowns above to select sector, year, and metric.
B13: 2. Navigate to the ACROSS_YEARS sheet to see the time-series line chart.
B14: 3. Navigate to the ACROSS_SECTORS sheet to see the sector comparison bar chart.
B15: 4. Charts update automatically when you change a selection above.
B17: Note: Charts are powered by helper tables on each chart sheet that use
B18: IFERROR/SUMPRODUCT formulas — no macros or VBA required.

Sheet ACROSS_YEARS
A1: Sector Medians Over Time
A3: → Change selections on CONTROL sheet to update this chart
A4: Sector: | B4: =CONTROL!C6 | C4: Metric: | D4: =CONTROL!C8
A7: Year | B7: Value
A8: 2011 | B8: =IFERROR(SUMPRODUCT((DATA!$A$2:$A$175=CONTROL!$C$6)*(DATA!$B$2:$B$175=2011)*INDEX(DATA!$C$2:$Q$175,0,MATCH(CONTROL!$C$8,DATA!$C$1:$Q$1,0))),"")
A9: 2012 | B9: =IFERROR(SUMPRODUCT((DATA!$A$2:$A$175=CONTROL!$C$6)*(DATA!$B$2:$B$175=2012)*INDEX(DATA!$C$2:$Q$175,0,MATCH(CONTROL!$C$8,DATA!$C$1:$Q$1,0))),"")
A10: 2013 | B10: =IFERROR(SUMPRODUCT((DATA!$A$2:$A$175=CONTROL!$C$6)*(DATA!$B$2:$B$175=2013)*INDEX(DATA!$C$2:$Q$175,0,MATCH(CONTROL!$C$8,DATA!$C$1:$Q$1,0))),"")
A11: 2014 | B11: =IFERROR(SUMPRODUCT((DATA!$A$2:$A$175=CONTROL!$C$6)*(DATA!$B$2:$B$175=2014)*INDEX(DATA!$C$2:$Q$175,0,MATCH(CONTROL!$C$8,DATA!$C$1:$Q$1,0))),"")
A12: 2015 | B12: =IFERROR(SUMPRODUCT((DATA!$A$2:$A$175=CONTROL!$C$6)*(DATA!$B$2:$B$175=2015)*INDEX(DATA!$C$2:$Q$175,0,MATCH(CONTROL!$C$8,DATA!$C$1:$Q$1,0))),"")
A13: 2016 | B13: =IFERROR(SUMPRODUCT((DATA!$A$2:$A$175=CONTROL!$C$6)*(DATA!$B$2:$B$175=2016)*INDEX(DATA!$C$2:$Q$175,0,MATCH(CONTROL!$C$8,DATA!$C$1:$Q$1,0))),"")
A14: 2017 | B14: =IFERROR(SUMPRODUCT((DATA!$A$2:$A$175=CONTROL!$C$6)*(DATA!$B$2:$B$175=2017)*INDEX(DATA!$C$2:$Q$175,0,MATCH(CONTROL!$C$8,DATA!$C$1:$Q$1,0))),"")
A15: 2018 | B15: =IFERROR(SUMPRODUCT((DATA!$A$2:$A$175=CONTROL!$C$6)*(DATA!$B$2:$B$175=2018)*INDEX(DATA!$C$2:$Q$175,0,MATCH(CONTROL!$C$8,DATA!$C$1:$Q$1,0))),"")
A16: 2019 | B16: =IFERROR(SUMPRODUCT((DATA!$A$2:$A$175=CONTROL!$C$6)*(DATA!$B$2:$B$175=2019)*INDEX(DATA!$C$2:$Q$175,0,MATCH(CONTROL!$C$8,DATA!$C$1:$Q$1,0))),"")
A17: 2020 | B17: =IFERROR(SUMPRODUCT((DATA!$A$2:$A$175=CONTROL!$C$6)*(DATA!$B$2:$B$175=2020)*INDEX(DATA!$C$2:$Q$175,0,MATCH(CONTROL!$C$8,DATA!$C$1:$Q$1,0))),"")
A18: 2021 | B18: =IFERROR(SUMPRODUCT((DATA!$A$2:$A$175=CONTROL!$C$6)*(DATA!$B$2:$B$175=2021)*INDEX(DATA!$C$2:$Q$175,0,MATCH(CONTROL!$C$8,DATA!$C$1:$Q$1,0))),"")
A19: 2022 | B19: =IFERROR(SUMPRODUCT((DATA!$A$2:$A$175=CONTROL!$C$6)*(DATA!$B$2:$B$175=2022)*INDEX(DATA!$C$2:$Q$175,0,MATCH(CONTROL!$C$8,DATA!$C$1:$Q$1,0))),"")
A20: 2023 | B20: =IFERROR(SUMPRODUCT((DATA!$A$2:$A$175=CONTROL!$C$6)*(DATA!$B$2:$B$175=2023)*INDEX(DATA!$C$2:$Q$175,0,MATCH(CONTROL!$C$8,DATA!$C$1:$Q$1,0))),"")
A21: 2024 | B21: =IFERROR(SUMPRODUCT((DATA!$A$2:$A$175=CONTROL!$C$6)*(DATA!$B$2:$B$175=2024)*INDEX(DATA!$C$2:$Q$175,0,MATCH(CONTROL!$C$8,DATA!$C$1:$Q$1,0))),"")
A22: 2025 | B22: =IFERROR(SUMPRODUCT((DATA!$A$2:$A$175=CONTROL!$C$6)*(DATA!$B$2:$B$175=2025)*INDEX(DATA!$C$2:$Q$175,0,MATCH(CONTROL!$C$8,DATA!$C$1:$Q$1,0))),"")
A23: 2026 | B23: =IFERROR(SUMPRODUCT((DATA!$A$2:$A$175=CONTROL!$C$6)*(DATA!$B$2:$B$175=2026)*INDEX(DATA!$C$2:$Q$175,0,MATCH(CONTROL!$C$8,DATA!$C$1:$Q$1,0))),"")

Sheet ACROSS_SECTORS
A1: Sector Medians — Cross-Sectional Snapshot
A3: → Change selections on CONTROL sheet to update this chart
A4: Year: | B4: =CONTROL!G6 | C4: Metric: | D4: =CONTROL!G8
A7: Sector | B7: Value
A8: Basic Materials | B8: =IFERROR(SUMPRODUCT((DATA!$A$2:$A$175="Basic Materials")*(DATA!$B$2:$B$175=VALUE(CONTROL!$G$6))*INDEX(DATA!$C$2:$Q$175,0,MATCH(CONTROL!$G$8,DATA!$C$1:$Q$1,0))),"")
A9: Communication Services | B9: =IFERROR(SUMPRODUCT((DATA!$A$2:$A$175="Communication Services")*(DATA!$B$2:$B$175=VALUE(CONTROL!$G$6))*INDEX(DATA!$C$2:$Q$175,0,MATCH(CONTROL!$G$8,DATA!$C$1:$Q$1,0))),"")
A10: Consumer Cyclical | B10: =IFERROR(SUMPRODUCT((DATA!$A$2:$A$175="Consumer Cyclical")*(DATA!$B$2:$B$175=VALUE(CONTROL!$G$6))*INDEX(DATA!$C$2:$Q$175,0,MATCH(CONTROL!$G$8,DATA!$C$1:$Q$1,0))),"")
A11: Consumer Defensive | B11: =IFERROR(SUMPRODUCT((DATA!$A$2:$A$175="Consumer Defensive")*(DATA!$B$2:$B$175=VALUE(CONTROL!$G$6))*INDEX(DATA!$C$2:$Q$175,0,MATCH(CONTROL!$G$8,DATA!$C$1:$Q$1,0))),"")
A12: Energy | B12: =IFERROR(SUMPRODUCT((DATA!$A$2:$A$175="Energy")*(DATA!$B$2:$B$175=VALUE(CONTROL!$G$6))*INDEX(DATA!$C$2:$Q$175,0,MATCH(CONTROL!$G$8,DATA!$C$1:$Q$1,0))),"")
A13: Financial Services | B13: =IFERROR(SUMPRODUCT((DATA!$A$2:$A$175="Financial Services")*(DATA!$B$2:$B$175=VALUE(CONTROL!$G$6))*INDEX(DATA!$C$2:$Q$175,0,MATCH(CONTROL!$G$8,DATA!$C$1:$Q$1,0))),"")
A14: Healthcare | B14: =IFERROR(SUMPRODUCT((DATA!$A$2:$A$175="Healthcare")*(DATA!$B$2:$B$175=VALUE(CONTROL!$G$6))*INDEX(DATA!$C$2:$Q$175,0,MATCH(CONTROL!$G$8,DATA!$C$1:$Q$1,0))),"")
A15: Industrials | B15: =IFERROR(SUMPRODUCT((DATA!$A$2:$A$175="Industrials")*(DATA!$B$2:$B$175=VALUE(CONTROL!$G$6))*INDEX(DATA!$C$2:$Q$175,0,MATCH(CONTROL!$G$8,DATA!$C$1:$Q$1,0))),"")
A16: Real Estate | B16: =IFERROR(SUMPRODUCT((DATA!$A$2:$A$175="Real Estate")*(DATA!$B$2:$B$175=VALUE(CONTROL!$G$6))*INDEX(DATA!$C$2:$Q$175,0,MATCH(CONTROL!$G$8,DATA!$C$1:$Q$1,0))),"")
A17: Technology | B17: =IFERROR(SUMPRODUCT((DATA!$A$2:$A$175="Technology")*(DATA!$B$2:$B$175=VALUE(CONTROL!$G$6))*INDEX(DATA!$C$2:$Q$175,0,MATCH(CONTROL!$G$8,DATA!$C$1:$Q$1,0))),"")
A18: Utilities | B18: =IFERROR(SUMPRODUCT((DATA!$A$2:$A$175="Utilities")*(DATA!$B$2:$B$175=VALUE(CONTROL!$G$6))*INDEX(DATA!$C$2:$Q$175,0,MATCH(CONTROL!$G$8,DATA!$C$1:$Q$1,0))),"")
